Workbook

Sheet Introduction
A1: MaGMa UCF Tool
A3: Version | B3: 1.0
A4: Date | B4: 15.11.2017
A5: https://www.betaalvereniging.nl/veiligheid/publiek-private-samenwerking/

Sheet Model
B1: MaGMa UCF Tool - Model
B2: The model used in the MaGMA UCF tool is based on the MaGMA model presented in the document. As described in the document, MaGMa consists of 3 layers. These layers are the business layer, the threat layer and the implementation layer. Each of these layers corresponds to different parts of the MaGMa UCF tool. The business layer is implemented as a single tab 'Drivers' in which business drivers and compliance drivers can be entered. The Threat layer corresponds to the 'L1' and 'L2' tabs. The operational layer can be found in the 'L3' tabs and in the 'References' tab. The 'References' can be used to outline detection technology and log sources.

Sheet Usage
B1: MaGMa UCF Tool - Usage
B2: Introduction
B3: Usage of the MaGMa UCF tool is fairly straightforward. The L1 use cases have been predefined, as well as a number of L2 use cases. Use cases can be added at each level and should be connected by consistent use of identifiers (see section on identifiers). The L3 use cases provide the most detail. For these use cases, additional metrics should be set to indicate how well the use case is able to detect that particular threat. See the section on 'metrics' for more information. The UCF tool comes with 12 L1 use cases, 62 L2 use cases and 169 L3 use cases. The L3 use cases are based on the MITRE ATT&CK matrix for enterprise. (© 2017 The MITRE Corporation. This work is reproduced and distributed with the permission of The MITRE Corporation.) For additional guidance, please see the MaGMa framework document. This work is licensed under a Creative Commons License. For the full license description, see: https://creativecommons.org/licenses/by/3.0/
B5: Identifiers
B6: Identifiers are used throughout the tool for L1, L2 and L3 use cases. It is of vital importance to use consistent identifiers, so that the tool is able to connect each layer of the use case to a higher level. This connection is used for calculation of overall results, and average scoring. L1 use cases must have a 2-character identifier, L2 use cases must have an additional 3-character identifier, separated using a hyphen.
B8: An example: the second L1 use case is 'Delivery'. Its identifier is 'DE'. The corresponding L2 use cases are 'Web based malware delivery', 'Email based malware delivery' and 'Physical malware delivery'. Each of these L2 use cases starts out with the L1 prefix 'DE' and have a additional 3 character identifier. Web based malware delivery has the identifier 'DE-WEB'. This allows the tool to connect L2 to L1. The L3 use cases are identified by adding a sequence number 'DE-WEB-01' and 'DE-WEB-02'.
B10: Metrics
B11: There are 3 metrics used in the MaGMa UCF tool. Each of these metrics is entered in the L3 layer of the use cases as a percentage between 0 and 100. The granularity is something your organization should determine for yourself. The L2 and L1 layers calculate averages of these L3 metrics. The following metrics are used:
B12: Effectiveness | C12: This metric is used to determine the effectiveness of the L3 detection mechanism. For example, a proxy inspecting traffic is much less effective if it is not able to inspect HTTPS traffic.
B13: Implementation | C13: This metric is used to determine the level in which the L3 detection mechanism is implemented. For example, the implementation level of an IDS is much lower if the ruleset is incomplete or has not been tuned.
B14: Coverage | C14: This metric is used to determine the level in which the L3 detection mechanism covers the use case. For example, a use case focused on firewall events has less coverage if not all traffic is routed through the connected firewall.
B15: Weight | C15: This metric is a calculated overall score of effectiveness, implementation and coverage.
B16: Potential | C16: This metric is a calculated value that indicates how much improvement can be gained by investing in coverage and implementation.
B18: Adding use cases
B19: Adding use cases to the framework can be done at 3 levels: L1, L2 and L3.
B20: L1 | C20: L1 use cases can be added in the 'L1' tab. First, unhide the table headers in that tab. Then simply insert a new use case by copying an existing use case row. This way, all formulas and conditional formatting are automatically retained and updated. Make sure you provide the use case with a unique 2 character identifier.
B21: L2 | C21: L2 use cases are added to the 'L2' tab. To add a new use case, simply copy the current last row and insert it below that row. This will automatically update all formulas. Now, update the fields: identifier, use case name, description, actors and both business and compliance drivers. The columns 'A' and 'B', as well as the columns 'G' to 'L' should be automatically updated to reflect the new use case, do not manually overwrite the information in these columns. Note that no information may be available for those columns as L3 use cases will not be in place yet. Make sure you provide the use case with a unique identifier consisting of the L1 use case identifier, followed by a hyphen and a 3-character L2 identifier. The field will be marked with a red color if there is an overlapping identifier or description.
B22: L3 | C22: L3 use cases are added to the 'L3' tab. Like L1 and L2, add a use case by copying an existing row and placing it at the bottom. Columns 'A' to 'E' should be automatically updated once the correct identifier has been entered, do not manually overwrite the information in these columns. Make sure you provide the use case with a unique identifier consisting of the L2 identifier, followed by a hyphen and a number. Again, the field will be marked with a red color if there is an overlapping identifier or description.
B24: Example of use cases and metrics
B25: The following is an example of use cases and metrics, based on data exfiltration by malware, detected by proxy logs and routers.

Sheet Results
B2: Overall Results
B3: Detection Average | D3: Detection Gap | G3: Average Effectiveness | H3: Average Implementation | I3: Average Scope | J3: Average Weight | K3: Average Growth Potential
B4: ='L1 UC'!G19 -> 0 | D4: ='L1 UC'!G20 -> 1 | G4: ='L1 UC'!I19 -> 0 | H4: ='L1 UC'!J19 -> 0 | I4: ='L1 UC'!K19 -> 0 | J4: ='L1 UC'!L19 -> 0 | K4: ='L1 UC'!M19 -> 1
G6: Business Drivers | K6: =COUNTA(Drivers!C8:C13) -> 6
G7: Compliance Drivers | K7: =COUNTA(Drivers!C21:C35) -> 15
G8: L1 Count | K8: =COUNTA('L1 UC'!C4:C14) -> 10
G9: L2 Count | K9: =COUNTIF('L2 UC'!C2:C200,"?*") -> 38
G10: L3 Count | K10: =COUNTIF('L3 UC'!F2:F500,"?*") -> 0
G11: Detection Technologies | K11: =SUMPRODUCT(('L3 UC'!T2:T218<>"")/COUNTIF('L3 UC'!T2:T218,'L3 UC'!T2:T218&"")) -> 0
G12: Log/Data Source types | K12: =SUMPRODUCT(('L3 UC'!S2:S218<>"")/COUNTIF('L3 UC'!S2:S218,'L3 UC'!S2:S218&"")) -> 0

Sheet L1 UC
C1: Strategic Overview
A2: Threat category | C2: L1 Use Case Identifier | D2: Use Case Name | E2: Purpose | F2: Stakeholders | G2: #L2 UC related | H2: #L3 UC related | I2: Effectiveness | J2: Implementation | K2: Coverage | L2: Weight | M2: Potential | N2: Cumulative IN weight | O2: Cumulative THROUGH weight | P2: OUT weight | Q2: RISK SCORE | R2: Description
B3: Unified Kill Chain Cumulative Risk (IN - THROUGH)
C4: IN | D4: Cumulative IN risk | G4: =COUNTIF('L2 UC'!$B:$B,$C4) -> 9 | H4: =COUNTIF('L3 UC'!$C:$C,$C4) -> 0 | I4: =IFERROR(AVERAGEIF('L2 UC'!$B:$B,$C4,'L2 UC'!$H:$H),0) -> 0 | J4: =IFERROR(AVERAGEIF('L2 UC'!$B:$B,$C4,'L2 UC'!$I:$I),0) -> 0 | K4: =IFERROR(AVERAGEIF('L2 UC'!$B:$B,$C4,'L2 UC'!$J:$J),0) -> 0 | L4: =IFERROR(AVERAGEIF('L2 UC'!$B:$B,$C4,'L2 UC'!$K:$K),0) -> 0 | M4: =1-$L4 -> 1 | R4: Cumulative risk of IN stages and techniques, serving as a risk amplifier for the business risks
C5: THR | D5: Cumulative THROUGH risk | G5: =COUNTIF('L2 UC'!$B:$B,$C5) -> 6 | H5: =COUNTIF('L3 UC'!$C:$C,$C5) -> 0 | I5: =IFERROR(AVERAGEIF('L2 UC'!$B:$B,$C5,'L2 UC'!$H:$H),0) -> 0 | J5: =IFERROR(AVERAGEIF('L2 UC'!$B:$B,$C5,'L2 UC'!$I:$I),0) -> 0 | K5: =IFERROR(AVERAGEIF('L2 UC'!$B:$B,$C5,'L2 UC'!$J:$J),0) -> 0 | L5: =IFERROR(AVERAGEIF('L2 UC'!$B:$B,$C5,'L2 UC'!$K:$K),0) -> 0 | M5: =1-$L5 -> 1 | R5: Cumulative risk of THROUGH stages and techniques, serving as a risk amplifier for the business risks
B6: Business risks (Unified Kill Chain OUT)
C7: FIN | D7: Financial Loss | G7: =COUNTIF('L2 UC'!$B:$B,$C7) -> 0 | H7: =COUNTIF('L3 UC'!$C:$C,$C7) -> 0 | I7: =IFERROR(AVERAGEIF('L2 UC'!$B:$B,$C7,'L2 UC'!$H:$H),0) -> 0 | J7: =IFERROR(AVERAGEIF('L2 UC'!$B:$B,$C7,'L2 UC'!$I:$I),0) -> 0 | K7: =IFERROR(AVERAGEIF('L2 UC'!$B:$B,$C7,'L2 UC'!$J:$J),0) -> 0 | L7: =IFERROR(AVERAGEIF('L2 UC'!$B:$B,$C7,'L2 UC'!$K:$K),0) -> 0 | M7: =1-$L7 -> 1 | Q7: =MAX(0,1-(($L$4*$N7)+($L$5*$O7)+($L7*$P7))) -> 1 | R7: Any tampering of critical business systems which causes or further enables theft of virtual or physical assets via existing or current channels.
C8: DOS | D8: Denial of Service | G8: =COUNTIF('L2 UC'!$B:$B,$C8) -> 3 | H8: =COUNTIF('L3 UC'!$C:$C,$C8) -> 0 | I8: =IFERROR(AVERAGEIF('L2 UC'!$B:$B,$C8,'L2 UC'!$H:$H),0) -> 0 | J8: =IFERROR(AVERAGEIF('L2 UC'!$B:$B,$C8,'L2 UC'!$I:$I),0) -> 0 | K8: =IFERROR(AVERAGEIF('L2 UC'!$B:$B,$C8,'L2 UC'!$J:$J),0) -> 0 | L8: =IFERROR(AVERAGEIF('L2 UC'!$B:$B,$C8,'L2 UC'!$K:$K),0) -> 0 | M8: =1-$L8 -> 1 | Q8: =MAX(0,1-(($L$4*$N8)+($L$5*$O8)+($L8*$P8))) -> 1 | R8: Any Denial of Service attack, optionally distributed with the goal of causing outages. IN: reconnaissance & scanning THROUGH: not applicable OUT: DDoS attack impact
C9: ESP | D9: Espionage / Data Theft | G9: =COUNTIF('L2 UC'!$B:$B,$C9) -> 5 | H9: =COUNTIF('L3 UC'!$C:$C,$C9) -> 0 | I9: =IFERROR(AVERAGEIF('L2 UC'!$B:$B,$C9,'L2 UC'!$H:$H),0) -> 0 | J9: =IFERROR(AVERAGEIF('L2 UC'!$B:$B,$C9,'L2 UC'!$I:$I),0) -> 0 | K9: =IFERROR(AVERAGEIF('L2 UC'!$B:$B,$C9,'L2 UC'!$J:$J),0) -> 0 | L9: =IFERROR(AVERAGEIF('L2 UC'!$B:$B,$C9,'L2 UC'!$K:$K),0) -> 0 | M9: =1-$L9 -> 1 | Q9: =MAX(0,1-(($L$4*$N9)+($L$5*$O9)+($L9*$P9))) -> 1 | R9: Corporate espionage aimed at stealing proprietary intellectual property IN: intial compromise and foothold THROUGH: lateral movement, privilege elevation, identifying intellectual property, collection & staging OUT: exfiltration
C10: CEO | D10: CEO Fraud | G10: =COUNTIF('L2 UC'!$B:$B,$C10) -> 2 | H10: =COUNTIF('L3 UC'!$C:$C,$C10) -> 0 | I10: =IFERROR(AVERAGEIF('L2 UC'!$B:$B,$C10,'L2 UC'!$H:$H),0) -> 0 | J10: =IFERROR(AVERAGEIF('L2 UC'!$B:$B,$C10,'L2 UC'!$I:$I),0) -> 0 | K10: =IFERROR(AVERAGEIF('L2 UC'!$B:$B,$C10,'L2 UC'!$J:$J),0) -> 0 | L10: =IFERROR(AVERAGEIF('L2 UC'!$B:$B,$C10,'L2 UC'!$K:$K),0) -> 0 | M10: =1-$L10 -> 1 | Q10: =MAX(0,1-(($L$4*$N10)+($L$5*$O10)+($L10*$P10))) -> 1 | R10: Attempts by criminals to impersonate the organization's CEO or other board-level executive and to have the victim transfer large amounts of money. IN: intial compromise and foothold THROUGH: lateral movement, privilege elevation, identifying C-level mailboxes, obtaining credentials and/or compromising email server OUT: sending email
C11: EXT | D11: Extortion / Ransomware | G11: =COUNTIF('L2 UC'!$B:$B,$C11) -> 1 | H11: =COUNTIF('L3 UC'!$C:$C,$C11) -> 0 | I11: =IFERROR(AVERAGEIF('L2 UC'!$B:$B,$C11,'L2 UC'!$H:$H),0) -> 0 | J11: =IFERROR(AVERAGEIF('L2 UC'!$B:$B,$C11,'L2 UC'!$I:$I),0) -> 0 | K11: =IFERROR(AVERAGEIF('L2 UC'!$B:$B,$C11,'L2 UC'!$J:$J),0) -> 0 | L11: =IFERROR(AVERAGEIF('L2 UC'!$B:$B,$C11,'L2 UC'!$K:$K),0) -> 0 | M11: =1-$L11 -> 1 | Q11: =MAX(0,1-(($L$4*$N11)+($L$5*$O11)+($L11*$P11))) -> 1
C12: SAB | D12: Sabotage / Destruction | G12: =COUNTIF('L2 UC'!$B:$B,$C12) -> 4 | H12: =COUNTIF('L3 UC'!$C:$C,$C12) -> 0 | I12: =IFERROR(AVERAGEIF('L2 UC'!$B:$B,$C12,'L2 UC'!$H:$H),0) -> 0 | J12: =IFERROR(AVERAGEIF('L2 UC'!$B:$B,$C12,'L2 UC'!$I:$I),0) -> 0 | K12: =IFERROR(AVERAGEIF('L2 UC'!$B:$B,$C12,'L2 UC'!$J:$J),0) -> 0 | L12: =IFERROR(AVERAGEIF('L2 UC'!$B:$B,$C12,'L2 UC'!$K:$K),0) -> 0 | M12: =1-$L12 -> 1 | Q12: =MAX(0,1-(($L$4*$N12)+($L$5*$O12)+($L12*$P12))) -> 1 | R12: Any action to destroy/damage organizational and personal asset, information or reputation with the goal of causing financial damage or service outages e.g.: social media data posting, doxing, etc.
C13: INS | D13: Insider Threat | G13: =COUNTIF('L2 UC'!$B:$B,$C13) -> 0 | H13: =COUNTIF('L3 UC'!$C:$C,$C13) -> 0 | I13: =IFERROR(AVERAGEIF('L2 UC'!$B:$B,$C13,'L2 UC'!$H:$H),0) -> 0 | J13: =IFERROR(AVERAGEIF('L2 UC'!$B:$B,$C13,'L2 UC'!$I:$I),0) -> 0 | K13: =IFERROR(AVERAGEIF('L2 UC'!$B:$B,$C13,'L2 UC'!$J:$J),0) -> 0 | L13: =IFERROR(AVERAGEIF('L2 UC'!$B:$B,$C13,'L2 UC'!$K:$K),0) -> 0 | M13: =1-$L13 -> 1 | Q13: =MAX(0,1-(($L$4*$N13)+($L$5*$O13)+($L13*$P13))) -> 1
C14: POL | D14: Policy Violations | G14: =COUNTIF('L2 UC'!$B:$B,$C14) -> 8 | H14: =COUNTIF('L3 UC'!$C:$C,$C14) -> 0 | I14: =IFERROR(AVERAGEIF('L2 UC'!$B:$B,$C14,'L2 UC'!$H:$H),0) -> 0 | J14: =IFERROR(AVERAGEIF('L2 UC'!$B:$B,$C14,'L2 UC'!$I:$I),0) -> 0 | K14: =IFERROR(AVERAGEIF('L2 UC'!$B:$B,$C14,'L2 UC'!$J:$J),0) -> 0 | L14: =IFERROR(AVERAGEIF('L2 UC'!$B:$B,$C14,'L2 UC'!$K:$K),0) -> 0 | M14: =1-$L14 -> 1 | Q14: =MAX(0,1-(($L$4*$N14)+($L$5*$O14)+($L14*$P14))) -> 1 | R14: Illegal sites, service account usage, presence of vulnerabilities, Unauthorized process launched, etc..
C16: Overall Performance
C18: Description | G18: SOC Score | I18: Average Effectiveness | J18: Average Implementation | K18: Average Scope | L18: Average Weight | M18: Average Growth Potential
C19: SOC Detection Average | G19: =L19 -> 0 | I19: =AVERAGE($I$4:$I$5,$I$7:$I$14) -> 0 | J19: =AVERAGE($J$4:$J$5,$J$7:$J$14) -> 0 | K19: =AVERAGE($K$4:$K$5,$K$7:$K$14) -> 0 | L19: =AVERAGE($L$4:$L$5,$L$7:$L$14) -> 0 | M19: =AVERAGE($M$4:$M$5,$M$7:$M$14) -> 1
C20: SOC Detection Gap (growth potential) | G20: =1-G19 -> 1
C22: Graphs
B24: Effectiveness, implementation and coverage per L1 use case | G24: Weight and potential per L1 use case | S24: Number of use cases per L1 use case

Sheet L2 UC
A1: L1 Use Case Name | B1: L1 Use Case Identifier | C1: L2 Use Case Identifier | D1: Use Case Name | E1: Use Case Description | F1: Actors | G1: #L3 UC related | H1: Avg Effectiveness | I1: Avg Implementation | J1: Avg Coverage | K1: Avg Weight | L1: Avg Potential | M1: Business Drivers | N1: Internal Policy | O1: External regulator #1 | P1: External regulator #2
A2: =IF($C2="","",IFERROR(VLOOKUP($B2,'L1 UC'!$C:$D,2,FALSE()),"")) -> Cumulative IN risk | B2: =IF($C2="","",LEFT($C2,FIND("-",$C2&"-")-1)) -> IN | C2: IN-REC | D2: Reconnaissance | G2: =IF($C2="","",COUNTIF('L3 UC'!$E:$E,$C2)) -> 0 | H2: =IF($C2="","",IFERROR(SUMIF('L3 UC'!$E:$E,$C2,'L3 UC'!$N:$N)/$G2,0)) -> 0 | I2: =IF($C2="","",IFERROR(SUMIF('L3 UC'!$E:$E,$C2,'L3 UC'!$O:$O)/$G2,0)) -> 0 | J2: =IF($C2="","",IFERROR(SUMIF('L3 UC'!$E:$E,$C2,'L3 UC'!$P:$P)/$G2,0)) -> 0 | K2: =IF($C2="","",IFERROR(SUMIF('L3 UC'!$E:$E,$C2,'L3 UC'!$Q:$Q)/$G2,0)) -> 0 | L2: =IF($C2="","",1-$K2) -> 1
A3: =IF($C3="","",IFERROR(VLOOKUP($B3,'L1 UC'!$C:$D,2,FALSE()),"")) -> Cumulative IN risk | B3: =IF($C3="","",LEFT($C3,FIND("-",$C3&"-")-1)) -> IN | C3: IN-RES | D3: Resource development | G3: =IF($C3="","",COUNTIF('L3 UC'!$E:$E,$C3)) -> 0 | H3: =IF($C3="","",IFERROR(SUMIF('L3 UC'!$E:$E,$C3,'L3 UC'!$N:$N)/$G3,0)) -> 0 | I3: =IF($C3="","",IFERROR(SUMIF('L3 UC'!$E:$E,$C3,'L3 UC'!$O:$O)/$G3,0)) -> 0 | J3: =IF($C3="","",IFERROR(SUMIF('L3 UC'!$E:$E,$C3,'L3 UC'!$P:$P)/$G3,0)) -> 0 | K3: =IF($C3="","",IFERROR(SUMIF('L3 UC'!$E:$E,$C3,'L3 UC'!$Q:$Q)/$G3,0)) -> 0 | L3: =IF($C3="","",1-$K3) -> 1
A4: =IF($C4="","",IFERROR(VLOOKUP($B4,'L1 UC'!$C:$D,2,FALSE()),"")) -> Cumulative IN risk | B4: =IF($C4="","",LEFT($C4,FIND("-",$C4&"-")-1)) -> IN | C4: IN-DEL | D4: Delivery | G4: =IF($C4="","",COUNTIF('L3 UC'!$E:$E,$C4)) -> 0 | H4: =IF($C4="","",IFERROR(SUMIF('L3 UC'!$E:$E,$C4,'L3 UC'!$N:$N)/$G4,0)) -> 0 | I4: =IF($C4="","",IFERROR(SUMIF('L3 UC'!$E:$E,$C4,'L3 UC'!$O:$O)/$G4,0)) -> 0 | J4: =IF($C4="","",IFERROR(SUMIF('L3 UC'!$E:$E,$C4,'L3 UC'!$P:$P)/$G4,0)) -> 0 | K4: =IF($C4="","",IFERROR(SUMIF('L3 UC'!$E:$E,$C4,'L3 UC'!$Q:$Q)/$G4,0)) -> 0 | L4: =IF($C4="","",1-$K4) -> 1
A5: =IF($C5="","",IFERROR(VLOOKUP($B5,'L1 UC'!$C:$D,2,FALSE()),"")) -> Cumulative IN risk | B5: =IF($C5="","",LEFT($C5,FIND("-",$C5&"-")-1)) -> IN | C5: IN-SOC | D5: Social Engineering | G5: =IF($C5="","",COUNTIF('L3 UC'!$E:$E,$C5)) -> 0 | H5: =IF($C5="","",IFERROR(SUMIF('L3 UC'!$E:$E,$C5,'L3 UC'!$N:$N)/$G5,0)) -> 0 | I5: =IF($C5="","",IFERROR(SUMIF('L3 UC'!$E:$E,$C5,'L3 UC'!$O:$O)/$G5,0)) -> 0 | J5: =IF($C5="","",IFERROR(SUMIF('L3 UC'!$E:$E,$C5,'L3 UC'!$P:$P)/$G5,0)) -> 0 | K5: =IF($C5="","",IFERROR(SUMIF('L3 UC'!$E:$E,$C5,'L3 UC'!$Q:$Q)/$G5,0)) -> 0 | L5: =IF($C5="","",1-$K5) -> 1
A6: =IF($C6="","",IFERROR(VLOOKUP($B6,'L1 UC'!$C:$D,2,FALSE()),"")) -> Cumulative IN risk | B6: =IF($C6="","",LEFT($C6,FIND("-",$C6&"-")-1)) -> IN | C6: IN-EXP | D6: Exploitation | G6: =IF($C6="","",COUNTIF('L3 UC'!$E:$E,$C6)) -> 0 | H6: =IF($C6="","",IFERROR(SUMIF('L3 UC'!$E:$E,$C6,'L3 UC'!$N:$N)/$G6,0)) -> 0 | I6: =IF($C6="","",IFERROR(SUMIF('L3 UC'!$E:$E,$C6,'L3 UC'!$O:$O)/$G6,0)) -> 0 | J6: =IF($C6="","",IFERROR(SUMIF('L3 UC'!$E:$E,$C6,'L3 UC'!$P:$P)/$G6,0)) -> 0 | K6: =IF($C6="","",IFERROR(SUMIF('L3 UC'!$E:$E,$C6,'L3 UC'!$Q:$Q)/$G6,0)) -> 0 | L6: =IF($C6="","",1-$K6) -> 1
A7: =IF($C7="","",IFERROR(VLOOKUP($B7,'L1 UC'!$C:$D,2,FALSE()),"")) -> Cumulative IN risk | B7: =IF($C7="","",LEFT($C7,FIND("-",$C7&"-")-1)) -> IN | C7: IN-PER | D7: Persistence | G7: =IF($C7="","",COUNTIF('L3 UC'!$E:$E,$C7)) -> 0 | H7: =IF($C7="","",IFERROR(SUMIF('L3 UC'!$E:$E,$C7,'L3 UC'!$N:$N)/$G7,0)) -> 0 | I7: =IF($C7="","",IFERROR(SUMIF('L3 UC'!$E:$E,$C7,'L3 UC'!$O:$O)/$G7,0)) -> 0 | J7: =IF($C7="","",IFERROR(SUMIF('L3 UC'!$E:$E,$C7,'L3 UC'!$P:$P)/$G7,0)) -> 0 | K7: =IF($C7="","",IFERROR(SUMIF('L3 UC'!$E:$E,$C7,'L3 UC'!$Q:$Q)/$G7,0)) -> 0 | L7: =IF($C7="","",1-$K7) -> 1
A8: =IF($C8="","",IFERROR(VLOOKUP($B8,'L1 UC'!$C:$D,2,FALSE()),"")) -> Cumulative IN risk | B8: =IF($C8="","",LEFT($C8,FIND("-",$C8&"-")-1)) -> IN | C8: IN-DEF | D8: Defense Evasion | G8: =IF($C8="","",COUNTIF('L3 UC'!$E:$E,$C8)) -> 0 | H8: =IF($C8="","",IFERROR(SUMIF('L3 UC'!$E:$E,$C8,'L3 UC'!$N:$N)/$G8,0)) -> 0 | I8: =IF($C8="","",IFERROR(SUMIF('L3 UC'!$E:$E,$C8,'L3 UC'!$O:$O)/$G8,0)) -> 0 | J8: =IF($C8="","",IFERROR(SUMIF('L3 UC'!$E:$E,$C8,'L3 UC'!$P:$P)/$G8,0)) -> 0 | K8: =IF($C8="","",IFERROR(SUMIF('L3 UC'!$E:$E,$C8,'L3 UC'!$Q:$Q)/$G8,0)) -> 0 | L8: =IF($C8="","",1-$K8) -> 1
A9: =IF($C9="","",IFERROR(VLOOKUP($B9,'L1 UC'!$C:$D,2,FALSE()),"")) -> Cumulative IN risk | B9: =IF($C9="","",LEFT($C9,FIND("-",$C9&"-")-1)) -> IN | C9: IN-CNC | D9: Command & Control | G9: =IF($C9="","",COUNTIF('L3 UC'!$E:$E,$C9)) -> 0 | H9: =IF($C9="","",IFERROR(SUMIF('L3 UC'!$E:$E,$C9,'L3 UC'!$N:$N)/$G9,0)) -> 0 | I9: =IF($C9="","",IFERROR(SUMIF('L3 UC'!$E:$E,$C9,'L3 UC'!$O:$O)/$G9,0)) -> 0 | J9: =IF($C9="","",IFERROR(SUMIF('L3 UC'!$E:$E,$C9,'L3 UC'!$P:$P)/$G9,0)) -> 0 | K9: =IF($C9="","",IFERROR(SUMIF('L3 UC'!$E:$E,$C9,'L3 UC'!$Q:$Q)/$G9,0)) -> 0 | L9: =IF($C9="","",1-$K9) -> 1
A10: =IF($C10="","",IFERROR(VLOOKUP($B10,'L1 UC'!$C:$D,2,FALSE()),"")) -> Cumulative IN risk | B10: =IF($C10="","",LEFT($C10,FIND("-",$C10&"-")-1)) -> IN | C10: IN-PHY | D10: Physical compromise | G10: =IF($C10="","",COUNTIF('L3 UC'!$E:$E,$C10)) -> 0 | H10: =IF($C10="","",IFERROR(SUMIF('L3 UC'!$E:$E,$C10,'L3 UC'!$N:$N)/$G10,0)) -> 0 | I10: =IF($C10="","",IFERROR(SUMIF('L3 UC'!$E:$E,$C10,'L3 UC'!$O:$O)/$G10,0)) -> 0 | J10: =IF($C10="","",IFERROR(SUMIF('L3 UC'!$E:$E,$C10,'L3 UC'!$P:$P)/$G10,0)) -> 0 | K10: =IF($C10="","",IFERROR(SUMIF('L3 UC'!$E:$E,$C10,'L3 UC'!$Q:$Q)/$G10,0)) -> 0 | L10: =IF($C10="","",1-$K10) -> 1
A11: =IF($C11="","",IFERROR(VLOOKUP($B11,'L1 UC'!$C:$D,2,FALSE()),"")) -> Cumulative THROUGH risk | B11: =IF($C11="","",LEFT($C11,FIND("-",$C11&"-")-1)) -> THR | C11: THR-PIV | D11: Pivoting | E11: Tunneling traffic through a controlled system to other systems that are not directly accessible | G11: =IF($C11="","",COUNTIF('L3 UC'!$E:$E,$C11)) -> 0 | H11: =IF($C11="","",IFERROR(SUMIF('L3 UC'!$E:$E,$C11,'L3 UC'!$N:$N)/$G11,0)) -> 0 | I11: =IF($C11="","",IFERROR(SUMIF('L3 UC'!$E:$E,$C11,'L3 UC'!$O:$O)/$G11,0)) -> 0 | J11: =IF($C11="","",IFERROR(SUMIF('L3 UC'!$E:$E,$C11,'L3 UC'!$P:$P)/$G11,0)) -> 0 | K11: =IF($C11="","",IFERROR(SUMIF('L3 UC'!$E:$E,$C11,'L3 UC'!$Q:$Q)/$G11,0)) -> 0 | L11: =IF($C11="","",1-$K11) -> 1
A12: =IF($C12="","",IFERROR(VLOOKUP($B12,'L1 UC'!$C:$D,2,FALSE()),"")) -> Cumulative THROUGH risk | B12: =IF($C12="","",LEFT($C12,FIND("-",$C12&"-")-1)) -> THR | C12: THR-DIS | D12: Discovery | E12: Techniques that allow an attacker to gain knowledge about a system and its network environment. | G12: =IF($C12="","",COUNTIF('L3 UC'!$E:$E,$C12)) -> 0 | H12: =IF($C12="","",IFERROR(SUMIF('L3 UC'!$E:$E,$C12,'L3 UC'!$N:$N)/$G12,0)) -> 0 | I12: =IF($C12="","",IFERROR(SUMIF('L3 UC'!$E:$E,$C12,'L3 UC'!$O:$O)/$G12,0)) -> 0 | J12: =IF($C12="","",IFERROR(SUMIF('L3 UC'!$E:$E,$C12,'L3 UC'!$P:$P)/$G12,0)) -> 0 | K12: =IF($C12="","",IFERROR(SUMIF('L3 UC'!$E:$E,$C12,'L3 UC'!$Q:$Q)/$G12,0)) -> 0 | L12: =IF($C12="","",1-$K12) -> 1
A13: =IF($C13="","",IFERROR(VLOOKUP($B13,'L1 UC'!$C:$D,2,FALSE()),"")) -> Cumulative THROUGH risk | B13: =IF($C13="","",LEFT($C13,FIND("-",$C13&"-")-1)) -> THR | C13: THR-PRI | D13: Privilege Escalation | E13: The result of techniques that provide an attacker with higher permissions on a system or network. | G13: =IF($C13="","",COUNTIF('L3 UC'!$E:$E,$C13)) -> 0 | H13: =IF($C13="","",IFERROR(SUMIF('L3 UC'!$E:$E,$C13,'L3 UC'!$N:$N)/$G13,0)) -> 0 | I13: =IF($C13="","",IFERROR(SUMIF('L3 UC'!$E:$E,$C13,'L3 UC'!$O:$O)/$G13,0)) -> 0 | J13: =IF($C13="","",IFERROR(SUMIF('L3 UC'!$E:$E,$C13,'L3 UC'!$P:$P)/$G13,0)) -> 0 | K13: =IF($C13="","",IFERROR(SUMIF('L3 UC'!$E:$E,$C13,'L3 UC'!$Q:$Q)/$G13,0)) -> 0 | L13: =IF($C13="","",1-$K13) -> 1
A14: =IF($C14="","",IFERROR(VLOOKUP($B14,'L1 UC'!$C:$D,2,FALSE()),"")) -> Cumulative THROUGH risk | B14: =IF($C14="","",LEFT($C14,FIND("-",$C14&"-")-1)) -> THR | C14: THR-EXE | D14: Execution | E14: Techniques that result in execution of attacker-controlled code on a local or remote system | G14: =IF($C14="","",COUNTIF('L3 UC'!$E:$E,$C14)) -> 0 | H14: =IF($C14="","",IFERROR(SUMIF('L3 UC'!$E:$E,$C14,'L3 UC'!$N:$N)/$G14,0)) -> 0 | I14: =IF($C14="","",IFERROR(SUMIF('L3 UC'!$E:$E,$C14,'L3 UC'!$O:$O)/$G14,0)) -> 0 | J14: =IF($C14="","",IFERROR(SUMIF('L3 UC'!$E:$E,$C14,'L3 UC'!$P:$P)/$G14,0)) -> 0 | K14: =IF($C14="","",IFERROR(SUMIF('L3 UC'!$E:$E,$C14,'L3 UC'!$Q:$Q)/$G14,0)) -> 0 | L14: =IF($C14="","",1-$K14) -> 1
A15: =IF($C15="","",IFERROR(VLOOKUP($B15,'L1 UC'!$C:$D,2,FALSE()),"")) -> Cumulative THROUGH risk | B15: =IF($C15="","",LEFT($C15,FIND("-",$C15&"-")-1)) -> THR | C15: THR-CRE | D15: Credential Access | E15: Techniques resulting in the access of, or control over, system, service or domain credentials. | G15: =IF($C15="","",COUNTIF('L3 UC'!$E:$E,$C15)) -> 0 | H15: =IF($C15="","",IFERROR(SUMIF('L3 UC'!$E:$E,$C15,'L3 UC'!$N:$N)/$G15,0)) -> 0 | I15: =IF($C15="","",IFERROR(SUMIF('L3 UC'!$E:$E,$C15,'L3 UC'!$O:$O)/$G15,0)) -> 0 | J15: =IF($C15="","",IFERROR(SUMIF('L3 UC'!$E:$E,$C15,'L3 UC'!$P:$P)/$G15,0)) -> 0 | K15: =IF($C15="","",IFERROR(SUMIF('L3 UC'!$E:$E,$C15,'L3 UC'!$Q:$Q)/$G15,0)) -> 0 | L15: =IF($C15="","",1-$K15) -> 1
A16: =IF($C16="","",IFERROR(VLOOKUP($B16,'L1 UC'!$C:$D,2,FALSE()),"")) -> Cumulative THROUGH risk | B16: =IF($C16="","",LEFT($C16,FIND("-",$C16&"-")-1)) -> THR | C16: THR-LAT | D16: Lateral Movement | E16: Techniques that enable an adversary to horizontally access and control other remote systems. | G16: =IF($C16="","",COUNTIF('L3 UC'!$E:$E,$C16)) -> 0 | H16: =IF($C16="","",IFERROR(SUMIF('L3 UC'!$E:$E,$C16,'L3 UC'!$N:$N)/$G16,0)) -> 0 | I16: =IF($C16="","",IFERROR(SUMIF('L3 UC'!$E:$E,$C16,'L3 UC'!$O:$O)/$G16,0)) -> 0 | J16: =IF($C16="","",IFERROR(SUMIF('L3 UC'!$E:$E,$C16,'L3 UC'!$P:$P)/$G16,0)) -> 0 | K16: =IF($C16="","",IFERROR(SUMIF('L3 UC'!$E:$E,$C16,'L3 UC'!$Q:$Q)/$G16,0)) -> 0 | L16: =IF($C16="","",1-$K16) -> 1
A17: =IF($C17="","",IFERROR(VLOOKUP($B17,'L1 UC'!$C:$D,2,FALSE()),"")) -> Extortion / Ransomware | B17: =IF($C17="","",LEFT($C17,FIND("-",$C17&"-")-1)) -> EXT | C17: EXT-EXT | D17: Extortion attempts | E17: Any attempts by attackers to gain financial compensation from the organization by not taking action. Such action may include DDoS attacks or sensitive information disclosure | G17: =IF($C17="","",COUNTIF('L3 UC'!$E:$E,$C17)) -> 0 | H17: =IF($C17="","",IFERROR(SUMIF('L3 UC'!$E:$E,$C17,'L3 UC'!$N:$N)/$G17,0)) -> 0 | I17: =IF($C17="","",IFERROR(SUMIF('L3 UC'!$E:$E,$C17,'L3 UC'!$O:$O)/$G17,0)) -> 0 | J17: =IF($C17="","",IFERROR(SUMIF('L3 UC'!$E:$E,$C17,'L3 UC'!$P:$P)/$G17,0)) -> 0 | K17: =IF($C17="","",IFERROR(SUMIF('L3 UC'!$E:$E,$C17,'L3 UC'!$Q:$Q)/$G17,0)) -> 0 | L17: =IF($C17="","",1-$K17) -> 1
A18: =IF($C18="","",IFERROR(VLOOKUP($B18,'L1 UC'!$C:$D,2,FALSE()),"")) -> CEO Fraud | B18: =IF($C18="","",LEFT($C18,FIND("-",$C18&"-")-1)) -> CEO | C18: CEO-BEC | D18: Business Email Compromise | E18: Compromise of the email server for purposes of fraud | G18: =IF($C18="","",COUNTIF('L3 UC'!$E:$E,$C18)) -> 0 | H18: =IF($C18="","",IFERROR(SUMIF('L3 UC'!$E:$E,$C18,'L3 UC'!$N:$N)/$G18,0)) -> 0 | I18: =IF($C18="","",IFERROR(SUMIF('L3 UC'!$E:$E,$C18,'L3 UC'!$O:$O)/$G18,0)) -> 0 | J18: =IF($C18="","",IFERROR(SUMIF('L3 UC'!$E:$E,$C18,'L3 UC'!$P:$P)/$G18,0)) -> 0 | K18: =IF($C18="","",IFERROR(SUMIF('L3 UC'!$E:$E,$C18,'L3 UC'!$Q:$Q)/$G18,0)) -> 0 | L18: =IF($C18="","",1-$K18) -> 1
A19: =IF($C19="","",IFERROR(VLOOKUP($B19,'L1 UC'!$C:$D,2,FALSE()),"")) -> CEO Fraud | B19: =IF($C19="","",LEFT($C19,FIND("-",$C19&"-")-1)) -> CEO | C19: CEO-SPF | D19: CEO spoofing attack | E19: Spoofing mail from high-level executives for purposes of fraud | G19: =IF($C19="","",COUNTIF('L3 UC'!$E:$E,$C19)) -> 0 | H19: =IF($C19="","",IFERROR(SUMIF('L3 UC'!$E:$E,$C19,'L3 UC'!$N:$N)/$G19,0)) -> 0 | I19: =IF($C19="","",IFERROR(SUMIF('L3 UC'!$E:$E,$C19,'L3 UC'!$O:$O)/$G19,0)) -> 0 | J19: =IF($C19="","",IFERROR(SUMIF('L3 UC'!$E:$E,$C19,'L3 UC'!$P:$P)/$G19,0)) -> 0 | K19: =IF($C19="","",IFERROR(SUMIF('L3 UC'!$E:$E,$C19,'L3 UC'!$Q:$Q)/$G19,0)) -> 0 | L19: =IF($C19="","",1-$K19) -> 1
A20: =IF($C20="","",IFERROR(VLOOKUP($B20,'L1 UC'!$C:$D,2,FALSE()),"")) -> Denial of Service | B20: =IF($C20="","",LEFT($C20,FIND("-",$C20&"-")-1)) -> DOS | C20: DOS-VOL | D20: Volume DDoS | E20: DDoS attack conducted by directing high volumes of (spoofed) traffic to out organization’s network | G20: =IF($C20="","",COUNTIF('L3 UC'!$E:$E,$C20)) -> 0 | H20: =IF($C20="","",IFERROR(SUMIF('L3 UC'!$E:$E,$C20,'L3 UC'!$N:$N)/$G20,0)) -> 0 | I20: =IF($C20="","",IFERROR(SUMIF('L3 UC'!$E:$E,$C20,'L3 UC'!$O:$O)/$G20,0)) -> 0 | J20: =IF($C20="","",IFERROR(SUMIF('L3 UC'!$E:$E,$C20,'L3 UC'!$P:$P)/$G20,0)) -> 0 | K20: =IF($C20="","",IFERROR(SUMIF('L3 UC'!$E:$E,$C20,'L3 UC'!$Q:$Q)/$G20,0)) -> 0 | L20: =IF($C20="","",1-$K20) -> 1
A21: =IF($C21="","",IFERROR(VLOOKUP($B21,'L1 UC'!$C:$D,2,FALSE()),"")) -> Denial of Service | B21: =IF($C21="","",LEFT($C21,FIND("-",$C21&"-")-1)) -> DOS | C21: DOS-PRO | D21: Protocol (D)Dos | E21: DDoS attack using protocol anomalies. Some network equipment or firewalls cannot effectively deal with some types of protocol attacks. Most commonly, this results in resource exhaustion | G21: =IF($C21="","",COUNTIF('L3 UC'!$E:$E,$C21)) -> 0 | H21: =IF($C21="","",IFERROR(SUMIF('L3 UC'!$E:$E,$C21,'L3 UC'!$N:$N)/$G21,0)) -> 0 | I21: =IF($C21="","",IFERROR(SUMIF('L3 UC'!$E:$E,$C21,'L3 UC'!$O:$O)/$G21,0)) -> 0 | J21: =IF($C21="","",IFERROR(SUMIF('L3 UC'!$E:$E,$C21,'L3 UC'!$P:$P)/$G21,0)) -> 0 | K21: =IF($C21="","",IFERROR(SUMIF('L3 UC'!$E:$E,$C21,'L3 UC'!$Q:$Q)/$G21,0)) -> 0 | L21: =IF($C21="","",1-$K21) -> 1
A22: =IF($C22="","",IFERROR(VLOOKUP($B22,'L1 UC'!$C:$D,2,FALSE()),"")) -> Denial of Service | B22: =IF($C22="","",LEFT($C22,FIND("-",$C22&"-")-1)) -> DOS | C22: DOS-APP | D22: Application (D)DoS | E22: (D)Dos attack conducted by mimicking high volumes of legitimate traffic to our web application servers | G22: =IF($C22="","",COUNTIF('L3 UC'!$E:$E,$C22)) -> 0 | H22: =IF($C22="","",IFERROR(SUMIF('L3 UC'!$E:$E,$C22,'L3 UC'!$N:$N)/$G22,0)) -> 0 | I22: =IF($C22="","",IFERROR(SUMIF('L3 UC'!$E:$E,$C22,'L3 UC'!$O:$O)/$G22,0)) -> 0 | J22: =IF($C22="","",IFERROR(SUMIF('L3 UC'!$E:$E,$C22,'L3 UC'!$P:$P)/$G22,0)) -> 0 | K22: =IF($C22="","",IFERROR(SUMIF('L3 UC'!$E:$E,$C22,'L3 UC'!$Q:$Q)/$G22,0)) -> 0 | L22: =IF($C22="","",1-$K22) -> 1
A23: =IF($C23="","",IFERROR(VLOOKUP($B23,'L1 UC'!$C:$D,2,FALSE()),"")) -> Espionage / Data Theft | B23: =IF($C23="","",LEFT($C23,FIND("-",$C23&"-")-1)) -> ESP | C23: ESP-END | D23: Espionage from endpoint | G23: =IF($C23="","",COUNTIF('L3 UC'!$E:$E,$C23)) -> 0 | H23: =IF($C23="","",IFERROR(SUMIF('L3 UC'!$E:$E,$C23,'L3 UC'!$N:$N)/$G23,0)) -> 0 | I23: =IF($C23="","",IFERROR(SUMIF('L3 UC'!$E:$E,$C23,'L3 UC'!$O:$O)/$G23,0)) -> 0 | J23: =IF($C23="","",IFERROR(SUMIF('L3 UC'!$E:$E,$C23,'L3 UC'!$P:$P)/$G23,0)) -> 0 | K23: =IF($C23="","",IFERROR(SUMIF('L3 UC'!$E:$E,$C23,'L3 UC'!$Q:$Q)/$G23,0)) -> 0 | L23: =IF($C23="","",1-$K23) -> 1
A24: =IF($C24="","",IFERROR(VLOOKUP($B24,'L1 UC'!$C:$D,2,FALSE()),"")) -> Espionage / Data Theft | B24: =IF($C24="","",LEFT($C24,FIND("-",$C24&"-")-1)) -> ESP | C24: ESP-SRV | D24: Espionage from servers / storage | G24: =IF($C24="","",COUNTIF('L3 UC'!$E:$E,$C24)) -> 0 | H24: =IF($C24="","",IFERROR(SUMIF('L3 UC'!$E:$E,$C24,'L3 UC'!$N:$N)/$G24,0)) -> 0 | I24: =IF($C24="","",IFERROR(SUMIF('L3 UC'!$E:$E,$C24,'L3 UC'!$O:$O)/$G24,0)) -> 0 | J24: =IF($C24="","",IFERROR(SUMIF('L3 UC'!$E:$E,$C24,'L3 UC'!$P:$P)/$G24,0)) -> 0 | K24: =IF($C24="","",IFERROR(SUMIF('L3 UC'!$E:$E,$C24,'L3 UC'!$Q:$Q)/$G24,0)) -> 0 | L24: =IF($C24="","",1-$K24) -> 1
A25: =IF($C25="","",IFERROR(VLOOKUP($B25,'L1 UC'!$C:$D,2,FALSE()),"")) -> Espionage / Data Theft | B25: =IF($C25="","",LEFT($C25,FIND("-",$C25&"-")-1)) -> ESP | C25: ESP-TRA | D25: Espionage from data in transit | G25: =IF($C25="","",COUNTIF('L3 UC'!$E:$E,$C25)) -> 0 | H25: =IF($C25="","",IFERROR(SUMIF('L3 UC'!$E:$E,$C25,'L3 UC'!$N:$N)/$G25,0)) -> 0 | I25: =IF($C25="","",IFERROR(SUMIF('L3 UC'!$E:$E,$C25,'L3 UC'!$O:$O)/$G25,0)) -> 0 | J25: =IF($C25="","",IFERROR(SUMIF('L3 UC'!$E:$E,$C25,'L3 UC'!$P:$P)/$G25,0)) -> 0 | K25: =IF($C25="","",IFERROR(SUMIF('L3 UC'!$E:$E,$C25,'L3 UC'!$Q:$Q)/$G25,0)) -> 0 | L25: =IF($C25="","",1-$K25) -> 1
A26: =IF($C26="","",IFERROR(VLOOKUP($B26,'L1 UC'!$C:$D,2,FALSE()),"")) -> Espionage / Data Theft | B26: =IF($C26="","",LEFT($C26,FIND("-",$C26&"-")-1)) -> ESP | C26: ESP-COL | D26: Collection | E26: Collection of information from various sources for espionage purposes | G26: =IF($C26="","",COUNTIF('L3 UC'!$E:$E,$C26)) -> 0 | H26: =IF($C26="","",IFERROR(SUMIF('L3 UC'!$E:$E,$C26,'L3 UC'!$N:$N)/$G26,0)) -> 0 | I26: =IF($C26="","",IFERROR(SUMIF('L3 UC'!$E:$E,$C26,'L3 UC'!$O:$O)/$G26,0)) -> 0 | J26: =IF($C26="","",IFERROR(SUMIF('L3 UC'!$E:$E,$C26,'L3 UC'!$P:$P)/$G26,0)) -> 0 | K26: =IF($C26="","",IFERROR(SUMIF('L3 UC'!$E:$E,$C26,'L3 UC'!$Q:$Q)/$G26,0)) -> 0 | L26: =IF($C26="","",1-$K26) -> 1
A27: =IF($C27="","",IFERROR(VLOOKUP($B27,'L1 UC'!$C:$D,2,FALSE()),"")) -> Espionage / Data Theft | B27: =IF($C27="","",LEFT($C27,FIND("-",$C27&"-")-1)) -> ESP | C27: ESP-EXF | D27: Exfiltration in espionage attack | E27: Exfiltration of collected information through various channels for espionsage purposes | G27: =IF($C27="","",COUNTIF('L3 UC'!$E:$E,$C27)) -> 0 | H27: =IF($C27="","",IFERROR(SUMIF('L3 UC'!$E:$E,$C27,'L3 UC'!$N:$N)/$G27,0)) -> 0 | I27: =IF($C27="","",IFERROR(SUMIF('L3 UC'!$E:$E,$C27,'L3 UC'!$O:$O)/$G27,0)) -> 0 | J27: =IF($C27="","",IFERROR(SUMIF('L3 UC'!$E:$E,$C27,'L3 UC'!$P:$P)/$G27,0)) -> 0 | K27: =IF($C27="","",IFERROR(SUMIF('L3 UC'!$E:$E,$C27,'L3 UC'!$Q:$Q)/$G27,0)) -> 0 | L27: =IF($C27="","",1-$K27) -> 1
A28: =IF($C28="","",IFERROR(VLOOKUP($B28,'L1 UC'!$C:$D,2,FALSE()),"")) -> Sabotage / Destruction | B28: =IF($C28="","",LEFT($C28,FIND("-",$C28&"-")-1)) -> SAB | C28: SAB-ICS | D28: ICS sabotage | E28: Sabotage or destruction of a system through means of computer. This can be done as part of a cover-up strategy or simply to disrupt business. | G28: =IF($C28="","",COUNTIF('L3 UC'!$E:$E,$C28)) -> 0 | H28: =IF($C28="","",IFERROR(SUMIF('L3 UC'!$E:$E,$C28,'L3 UC'!$N:$N)/$G28,0)) -> 0 | I28: =IF($C28="","",IFERROR(SUMIF('L3 UC'!$E:$E,$C28,'L3 UC'!$O:$O)/$G28,0)) -> 0 | J28: =IF($C28="","",IFERROR(SUMIF('L3 UC'!$E:$E,$C28,'L3 UC'!$P:$P)/$G28,0)) -> 0 | K28: =IF($C28="","",IFERROR(SUMIF('L3 UC'!$E:$E,$C28,'L3 UC'!$Q:$Q)/$G28,0)) -> 0 | L28: =IF($C28="","",1-$K28) -> 1
A29: =IF($C29="","",IFERROR(VLOOKUP($B29,'L1 UC'!$C:$D,2,FALSE()),"")) -> Sabotage / Destruction | B29: =IF($C29="","",LEFT($C29,FIND("-",$C29&"-")-1)) -> SAB | C29: SAB-ITA | D29: IT Asset sabotage | E29: Sabotage or an IT asset | G29: =IF($C29="","",COUNTIF('L3 UC'!$E:$E,$C29)) -> 0 | H29: =IF($C29="","",IFERROR(SUMIF('L3 UC'!$E:$E,$C29,'L3 UC'!$N:$N)/$G29,0)) -> 0 | I29: =IF($C29="","",IFERROR(SUMIF('L3 UC'!$E:$E,$C29,'L3 UC'!$O:$O)/$G29,0)) -> 0 | J29: =IF($C29="","",IFERROR(SUMIF('L3 UC'!$E:$E,$C29,'L3 UC'!$P:$P)/$G29,0)) -> 0 | K29: =IF($C29="","",IFERROR(SUMIF('L3 UC'!$E:$E,$C29,'L3 UC'!$Q:$Q)/$G29,0)) -> 0 | L29: =IF($C29="","",1-$K29) -> 1
A30: =IF($C30="","",IFERROR(VLOOKUP($B30,'L1 UC'!$C:$D,2,FALSE()),"")) -> Sabotage / Destruction | B30: =IF($C30="","",LEFT($C30,FIND("-",$C30&"-")-1)) -> SAB | C30: SAB-PHS | D30: Physical sabotage | E30: Physical sabotage of an asset. This is physical damage directly from the attacker, or physical damage as a result of industrial sabotage. In case of ICS, sabotage can lead to physical destruction and thus have safety impact as well. | G30: =IF($C30="","",COUNTIF('L3 UC'!$E:$E,$C30)) -> 0 | H30: =IF($C30="","",IFERROR(SUMIF('L3 UC'!$E:$E,$C30,'L3 UC'!$N:$N)/$G30,0)) -> 0 | I30: =IF($C30="","",IFERROR(SUMIF('L3 UC'!$E:$E,$C30,'L3 UC'!$O:$O)/$G30,0)) -> 0 | J30: =IF($C30="","",IFERROR(SUMIF('L3 UC'!$E:$E,$C30,'L3 UC'!$P:$P)/$G30,0)) -> 0 | K30: =IF($C30="","",IFERROR(SUMIF('L3 UC'!$E:$E,$C30,'L3 UC'!$Q:$Q)/$G30,0)) -> 0 | L30: =IF($C30="","",1-$K30) -> 1
A31: =IF($C31="","",IFERROR(VLOOKUP($B31,'L1 UC'!$C:$D,2,FALSE()),"")) -> Sabotage / Destruction | B31: =IF($C31="","",LEFT($C31,FIND("-",$C31&"-")-1)) -> SAB | C31: SAB-WEB | D31: Defacement | E31: Defacement of (most likely) organizational websites. Usually conducted by hacktivist actors | G31: =IF($C31="","",COUNTIF('L3 UC'!$E:$E,$C31)) -> 0 | H31: =IF($C31="","",IFERROR(SUMIF('L3 UC'!$E:$E,$C31,'L3 UC'!$N:$N)/$G31,0)) -> 0 | I31: =IF($C31="","",IFERROR(SUMIF('L3 UC'!$E:$E,$C31,'L3 UC'!$O:$O)/$G31,0)) -> 0 | J31: =IF($C31="","",IFERROR(SUMIF('L3 UC'!$E:$E,$C31,'L3 UC'!$P:$P)/$G31,0)) -> 0 | K31: =IF($C31="","",IFERROR(SUMIF('L3 UC'!$E:$E,$C31,'L3 UC'!$Q:$Q)/$G31,0)) -> 0 | L31: =IF($C31="","",1-$K31) -> 1
A32: =IF($C32="","",IFERROR(VLOOKUP($B32,'L1 UC'!$C:$D,2,FALSE()),"")) -> Policy Violations | B32: =IF($C32="","",LEFT($C32,FIND("-",$C32&"-")-1)) -> POL | C32: POL-ICS | D32: Illegal content streaming or usage of disallowed web service | E32: This could be copyrighted material, but also includes other illegal categories | G32: =IF($C32="","",COUNTIF('L3 UC'!$E:$E,$C32)) -> 0 | H32: =IF($C32="","",IFERROR(SUMIF('L3 UC'!$E:$E,$C32,'L3 UC'!$N:$N)/$G32,0)) -> 0 | I32: =IF($C32="","",IFERROR(SUMIF('L3 UC'!$E:$E,$C32,'L3 UC'!$O:$O)/$G32,0)) -> 0 | J32: =IF($C32="","",IFERROR(SUMIF('L3 UC'!$E:$E,$C32,'L3 UC'!$P:$P)/$G32,0)) -> 0 | K32: =IF($C32="","",IFERROR(SUMIF('L3 UC'!$E:$E,$C32,'L3 UC'!$Q:$Q)/$G32,0)) -> 0 | L32: =IF($C32="","",1-$K32) -> 1
A33: =IF($C33="","",IFERROR(VLOOKUP($B33,'L1 UC'!$C:$D,2,FALSE()),"")) -> Policy Violations | B33: =IF($C33="","",LEFT($C33,FIND("-",$C33&"-")-1)) -> POL | C33: POL-COM | D33: Insecure communication protocol | E33: Usage of protocols that are outdated and unsecure. Examples of such protocols are FTP and telnet | G33: =IF($C33="","",COUNTIF('L3 UC'!$E:$E,$C33)) -> 0 | H33: =IF($C33="","",IFERROR(SUMIF('L3 UC'!$E:$E,$C33,'L3 UC'!$N:$N)/$G33,0)) -> 0 | I33: =IF($C33="","",IFERROR(SUMIF('L3 UC'!$E:$E,$C33,'L3 UC'!$O:$O)/$G33,0)) -> 0 | J33: =IF($C33="","",IFERROR(SUMIF('L3 UC'!$E:$E,$C33,'L3 UC'!$P:$P)/$G33,0)) -> 0 | K33: =IF($C33="","",IFERROR(SUMIF('L3 UC'!$E:$E,$C33,'L3 UC'!$Q:$Q)/$G33,0)) -> 0 | L33: =IF($C33="","",1-$K33) -> 1
A34: =IF($C34="","",IFERROR(VLOOKUP($B34,'L1 UC'!$C:$D,2,FALSE()),"")) -> Policy Violations | B34: =IF($C34="","",LEFT($C34,FIND("-",$C34&"-")-1)) -> POL | C34: POL-VUL | D34: Vulnerable system or service | E34: Any vulnerable systems or applications / services that leave the system vulnerable for compromise | G34: =IF($C34="","",COUNTIF('L3 UC'!$E:$E,$C34)) -> 0 | H34: =IF($C34="","",IFERROR(SUMIF('L3 UC'!$E:$E,$C34,'L3 UC'!$N:$N)/$G34,0)) -> 0 | I34: =IF($C34="","",IFERROR(SUMIF('L3 UC'!$E:$E,$C34,'L3 UC'!$O:$O)/$G34,0)) -> 0 | J34: =IF($C34="","",IFERROR(SUMIF('L3 UC'!$E:$E,$C34,'L3 UC'!$P:$P)/$G34,0)) -> 0 | K34: =IF($C34="","",IFERROR(SUMIF('L3 UC'!$E:$E,$C34,'L3 UC'!$Q:$Q)/$G34,0)) -> 0 | L34: =IF($C34="","",1-$K34) -> 1
A35: =IF($C35="","",IFERROR(VLOOKUP($B35,'L1 UC'!$C:$D,2,FALSE()),"")) -> Policy Violations | B35: =IF($C35="","",LEFT($C35,FIND("-",$C35&"-")-1)) -> POL | C35: POL-PRC | D35: Unauthorized process launched | E35: Launch of an unauthorized process. Examples of such processes are psexec, powershell and the command prompt. Also covers unauthorized processes running as a service | G35: =IF($C35="","",COUNTIF('L3 UC'!$E:$E,$C35)) -> 0 | H35: =IF($C35="","",IFERROR(SUMIF('L3 UC'!$E:$E,$C35,'L3 UC'!$N:$N)/$G35,0)) -> 0 | I35: =IF($C35="","",IFERROR(SUMIF('L3 UC'!$E:$E,$C35,'L3 UC'!$O:$O)/$G35,0)) -> 0 | J35: =IF($C35="","",IFERROR(SUMIF('L3 UC'!$E:$E,$C35,'L3 UC'!$P:$P)/$G35,0)) -> 0 | K35: =IF($C35="","",IFERROR(SUMIF('L3 UC'!$E:$E,$C35,'L3 UC'!$Q:$Q)/$G35,0)) -> 0 | L35: =IF($C35="","",1-$K35) -> 1
A36: =IF($C36="","",IFERROR(VLOOKUP($B36,'L1 UC'!$C:$D,2,FALSE()),"")) -> Policy Violations | B36: =IF($C36="","",LEFT($C36,FIND("-",$C36&"-")-1)) -> POL | C36: POL-APP | D36: Illegal or aberrant application found on host | E36: Any application present on hosts that are not allowed by policy or are quite simply illegal. Examples of such applications are hacking tools and pirated software | G36: =IF($C36="","",COUNTIF('L3 UC'!$E:$E,$C36)) -> 0 | H36: =IF($C36="","",IFERROR(SUMIF('L3 UC'!$E:$E,$C36,'L3 UC'!$N:$N)/$G36,0)) -> 0 | I36: =IF($C36="","",IFERROR(SUMIF('L3 UC'!$E:$E,$C36,'L3 UC'!$O:$O)/$G36,0)) -> 0 | J36: =IF($C36="","",IFERROR(SUMIF('L3 UC'!$E:$E,$C36,'L3 UC'!$P:$P)/$G36,0)) -> 0 | K36: =IF($C36="","",IFERROR(SUMIF('L3 UC'!$E:$E,$C36,'L3 UC'!$Q:$Q)/$G36,0)) -> 0 | L36: =IF($C36="","",1-$K36) -> 1
A37: =IF($C37="","",IFERROR(VLOOKUP($B37,'L1 UC'!$C:$D,2,FALSE()),"")) -> Policy Violations | B37: =IF($C37="","",LEFT($C37,FIND("-",$C37&"-")-1)) -> POL | C37: POL-RES | D37: Resource abuse | E37: This use case is reserved for situations where systems are being abused, for example for bitcoin mining | G37: =IF($C37="","",COUNTIF('L3 UC'!$E:$E,$C37)) -> 0 | H37: =IF($C37="","",IFERROR(SUMIF('L3 UC'!$E:$E,$C37,'L3 UC'!$N:$N)/$G37,0)) -> 0 | I37: =IF($C37="","",IFERROR(SUMIF('L3 UC'!$E:$E,$C37,'L3 UC'!$O:$O)/$G37,0)) -> 0 | J37: =IF($C37="","",IFERROR(SUMIF('L3 UC'!$E:$E,$C37,'L3 UC'!$P:$P)/$G37,0)) -> 0 | K37: =IF($C37="","",IFERROR(SUMIF('L3 UC'!$E:$E,$C37,'L3 UC'!$Q:$Q)/$G37,0)) -> 0 | L37: =IF($C37="","",1-$K37) -> 1
... A39: =IF($C39="","",IFERROR(VLOOKUP($B39,'L1 UC'!$C:$D,2,FALSE()),"")) -> Policy Violations | B39: =IF($C39="","",LEFT($C39,FIND("-",$C39&"-")-1)) -> POL | C39: POL-POL | D39: Unauthorized modification of technical policy | E39: Unauthorized modification of configuration settings. This can be a compliance issue, where the configuration may result in a hardening baseline deviation. It can also be part of malicious activity | G39: =IF($C39="","",COUNTIF('L3 UC'!$E:$E,$C39)) -> 0 | H39: =IF($C39="","",IFERROR(SUMIF('L3 UC'!$E:$E,$C39,'L3 UC'!$N:$N)/$G39,0)) -> 0 | I39: =IF($C39="","",IFERROR(SUMIF('L3 UC'!$E:$E,$C39,'L3 UC'!$O:$O)/$G39,0)) -> 0 | J39: =IF($C39="","",IFERROR(SUMIF('L3 UC'!$E:$E,$C39,'L3 UC'!$P:$P)/$G39,0)) -> 0 | K39: =IF($C39="","",IFERROR(SUMIF('L3 UC'!$E:$E,$C39,'L3 UC'!$Q:$Q)/$G39,0)) -> 0 | L39: =IF($C39="","",1-$K39) -> 1
A40: =IF($C40="","",IFERROR(VLOOKUP($B40,'L1 UC'!$C:$D,2,FALSE()),"")) | B40: =IF($C40="","",LEFT($C40,FIND("-",$C40&"-")-1)) | G40: =IF($C40="","",COUNTIF('L3 UC'!$E:$E,$C40)) | H40: =IF($C40="","",IFERROR(SUMIF('L3 UC'!$E:$E,$C40,'L3 UC'!$N:$N)/$G40,0)) | I40: =IF($C40="","",IFERROR(SUMIF('L3 UC'!$E:$E,$C40,'L3 UC'!$O:$O)/$G40,0)) | J40: =IF($C40="","",IFERROR(SUMIF('L3 UC'!$E:$E,$C40,'L3 UC'!$P:$P)/$G40,0)) | K40: =IF($C40="","",IFERROR(SUMIF('L3 UC'!$E:$E,$C40,'L3 UC'!$Q:$Q)/$G40,0)) | L40: =IF($C40="","",1-$K40)
A41: =IF($C41="","",IFERROR(VLOOKUP($B41,'L1 UC'!$C:$D,2,FALSE()),"")) | B41: =IF($C41="","",LEFT($C41,FIND("-",$C41&"-")-1)) | G41: =IF($C41="","",COUNTIF('L3 UC'!$E:$E,$C41)) | H41: =IF($C41="","",IFERROR(SUMIF('L3 UC'!$E:$E,$C41,'L3 UC'!$N:$N)/$G41,0)) | I41: =IF($C41="","",IFERROR(SUMIF('L3 UC'!$E:$E,$C41,'L3 UC'!$O:$O)/$G41,0)) | J41: =IF($C41="","",IFERROR(SUMIF('L3 UC'!$E:$E,$C41,'L3 UC'!$P:$P)/$G41,0)) | K41: =IF($C41="","",IFERROR(SUMIF('L3 UC'!$E:$E,$C41,'L3 UC'!$Q:$Q)/$G41,0)) | L41: =IF($C41="","",1-$K41)
...

Sheet L3 UC
A1: # L3 use cases per L2 | B1: L1 Use Case Name | C1: L1 Use Case Identifier | D1: L2 Use Case Name | E1: L2 Use Case Identifier | F1: Rule Identifier | G1: Technical Use Case Name | H1: Use Case Description | I1: ATT&CK techniques | J1: MITRE ATTACK TACTIC | K1: Unified Kill Chain step | L1: Suggested L2 UC | M1: L2 override (optional) | N1: Effectiveness % | O1: Implementation % | P1: Visibility % | Q1: Weight (eff*impl*cvrge) | R1: Potential (100%-weight) | S1: Log source type | T1: Detection Technology | U1: Scope | V1: comments
A2: =IF($E2="","",COUNTIF($E:$E,$E2)) | B2: =IF($C2="","",VLOOKUP($C2,'L1 UC'!$C:$D,2,FALSE())) | C2: =IF($E2="","",LEFT($E2,FIND("-",$E2&"-")-1)) | D2: =IF($E2="","",VLOOKUP($E2,'L2 UC'!$C:$D,2,FALSE())) | E2: =IF($M2<>"",$M2,IF(COUNTIF('L2 UC'!$C:$C,$L2)>0,$L2,"")) | F2: =IF($E2="","",$E2&"-"&COUNTIF($E$2:$E2,$E2)) | G2: [ADD NAME HERE] | H2: [ADD DESCRIPTION HERE] | I2: [ADD TECHNIQUE HERE (e.g. T1059) TO AUTO-FILL L2 AND L1 SUGGESTIONS] | J2: =IF(OR($I2="",LEFT($I2,1)="["),"",IFERROR(VLOOKUP(TRIM(IF(ISNUMBER(FIND(",",$I2)),LEFT($I2,FIND(",",$I2)-1),$I2)),'Mitre Techniques'!$A:$C,3,FALSE()),"Unknown technique")) | K2: =IF($J2="","",IFERROR(VLOOKUP(IF(ISNUMBER(FIND(",",$J2)),LEFT($J2,FIND(",",$J2)-1),$J2),'ATTACK and Kill Chain mapping'!$A:$B,2,FALSE()),"")) | L2: =IF($J2="","",IFERROR(VLOOKUP(IF(ISNUMBER(FIND(",",$J2)),LEFT($J2,FIND(",",$J2)-1),$J2),'ATTACK and Kill Chain mapping'!$A:$D,4,FALSE()),"")) | Q2: =IF(COUNT($N2:$P2)=0,"",$N2*$O2*$P2) | R2: =IF($Q2="","",1-$Q2)
A3: =IF($E3="","",COUNTIF($E:$E,$E3)) | B3: =IF($C3="","",VLOOKUP($C3,'L1 UC'!$C:$D,2,FALSE())) | C3: =IF($E3="","",LEFT($E3,FIND("-",$E3&"-")-1)) | D3: =IF($E3="","",VLOOKUP($E3,'L2 UC'!$C:$D,2,FALSE())) | E3: =IF($M3<>"",$M3,IF(COUNTIF('L2 UC'!$C:$C,$L3)>0,$L3,"")) | F3: =IF($E3="","",$E3&"-"&COUNTIF($E$2:$E3,$E3)) | J3: =IF(OR($I3="",LEFT($I3,1)="["),"",IFERROR(VLOOKUP(TRIM(IF(ISNUMBER(FIND(",",$I3)),LEFT($I3,FIND(",",$I3)-1),$I3)),'Mitre Techniques'!$A:$C,3,FALSE()),"Unknown technique")) | K3: =IF($J3="","",IFERROR(VLOOKUP(IF(ISNUMBER(FIND(",",$J3)),LEFT($J3,FIND(",",$J3)-1),$J3),'ATTACK and Kill Chain mapping'!$A:$B,2,FALSE()),"")) | L3: =IF($J3="","",IFERROR(VLOOKUP(IF(ISNUMBER(FIND(",",$J3)),LEFT($J3,FIND(",",$J3)-1),$J3),'ATTACK and Kill Chain mapping'!$A:$D,4,FALSE()),"")) | Q3: =IF(COUNT($N3:$P3)=0,"",$N3*$O3*$P3) | R3: =IF($Q3="","",1-$Q3)
A4: =IF($E4="","",COUNTIF($E:$E,$E4)) | B4: =IF($C4="","",VLOOKUP($C4,'L1 UC'!$C:$D,2,FALSE())) | C4: =IF($E4="","",LEFT($E4,FIND("-",$E4&"-")-1)) | D4: =IF($E4="","",VLOOKUP($E4,'L2 UC'!$C:$D,2,FALSE())) | E4: =IF($M4<>"",$M4,IF(COUNTIF('L2 UC'!$C:$C,$L4)>0,$L4,"")) | F4: =IF($E4="","",$E4&"-"&COUNTIF($E$2:$E4,$E4)) | J4: =IF(OR($I4="",LEFT($I4,1)="["),"",IFERROR(VLOOKUP(TRIM(IF(ISNUMBER(FIND(",",$I4)),LEFT($I4,FIND(",",$I4)-1),$I4)),'Mitre Techniques'!$A:$C,3,FALSE()),"Unknown technique")) | K4: =IF($J4="","",IFERROR(VLOOKUP(IF(ISNUMBER(FIND(",",$J4)),LEFT($J4,FIND(",",$J4)-1),$J4),'ATTACK and Kill Chain mapping'!$A:$B,2,FALSE()),"")) | L4: =IF($J4="","",IFERROR(VLOOKUP(IF(ISNUMBER(FIND(",",$J4)),LEFT($J4,FIND(",",$J4)-1),$J4),'ATTACK and Kill Chain mapping'!$A:$D,4,FALSE()),"")) | Q4: =IF(COUNT($N4:$P4)=0,"",$N4*$O4*$P4) | R4: =IF($Q4="","",1-$Q4)
A5: =IF($E5="","",COUNTIF($E:$E,$E5)) | B5: =IF($C5="","",VLOOKUP($C5,'L1 UC'!$C:$D,2,FALSE())) | C5: =IF($E5="","",LEFT($E5,FIND("-",$E5&"-")-1)) | D5: =IF($E5="","",VLOOKUP($E5,'L2 UC'!$C:$D,2,FALSE())) | E5: =IF($M5<>"",$M5,IF(COUNTIF('L2 UC'!$C:$C,$L5)>0,$L5,"")) | F5: =IF($E5="","",$E5&"-"&COUNTIF($E$2:$E5,$E5)) | J5: =IF(OR($I5="",LEFT($I5,1)="["),"",IFERROR(VLOOKUP(TRIM(IF(ISNUMBER(FIND(",",$I5)),LEFT($I5,FIND(",",$I5)-1),$I5)),'Mitre Techniques'!$A:$C,3,FALSE()),"Unknown technique")) | K5: =IF($J5="","",IFERROR(VLOOKUP(IF(ISNUMBER(FIND(",",$J5)),LEFT($J5,FIND(",",$J5)-1),$J5),'ATTACK and Kill Chain mapping'!$A:$B,2,FALSE()),"")) | L5: =IF($J5="","",IFERROR(VLOOKUP(IF(ISNUMBER(FIND(",",$J5)),LEFT($J5,FIND(",",$J5)-1),$J5),'ATTACK and Kill Chain mapping'!$A:$D,4,FALSE()),"")) | Q5: =IF(COUNT($N5:$P5)=0,"",$N5*$O5*$P5) | R5: =IF($Q5="","",1-$Q5)
A6: =IF($E6="","",COUNTIF($E:$E,$E6)) | B6: =IF($C6="","",VLOOKUP($C6,'L1 UC'!$C:$D,2,FALSE())) | C6: =IF($E6="","",LEFT($E6,FIND("-",$E6&"-")-1)) | D6: =IF($E6="","",VLOOKUP($E6,'L2 UC'!$C:$D,2,FALSE())) | E6: =IF($M6<>"",$M6,IF(COUNTIF('L2 UC'!$C:$C,$L6)>0,$L6,"")) | F6: =IF($E6="","",$E6&"-"&COUNTIF($E$2:$E6,$E6)) | J6: =IF(OR($I6="",LEFT($I6,1)="["),"",IFERROR(VLOOKUP(TRIM(IF(ISNUMBER(FIND(",",$I6)),LEFT($I6,FIND(",",$I6)-1),$I6)),'Mitre Techniques'!$A:$C,3,FALSE()),"Unknown technique")) | K6: =IF($J6="","",IFERROR(VLOOKUP(IF(ISNUMBER(FIND(",",$J6)),LEFT($J6,FIND(",",$J6)-1),$J6),'ATTACK and Kill Chain mapping'!$A:$B,2,FALSE()),"")) | L6: =IF($J6="","",IFERROR(VLOOKUP(IF(ISNUMBER(FIND(",",$J6)),LEFT($J6,FIND(",",$J6)-1),$J6),'ATTACK and Kill Chain mapping'!$A:$D,4,FALSE()),"")) | Q6: =IF(COUNT($N6:$P6)=0,"",$N6*$O6*$P6) | R6: =IF($Q6="","",1-$Q6)
A7: =IF($E7="","",COUNTIF($E:$E,$E7)) | B7: =IF($C7="","",VLOOKUP($C7,'L1 UC'!$C:$D,2,FALSE())) | C7: =IF($E7="","",LEFT($E7,FIND("-",$E7&"-")-1)) | D7: =IF($E7="","",VLOOKUP($E7,'L2 UC'!$C:$D,2,FALSE())) | E7: =IF($M7<>"",$M7,IF(COUNTIF('L2 UC'!$C:$C,$L7)>0,$L7,"")) | F7: =IF($E7="","",$E7&"-"&COUNTIF($E$2:$E7,$E7)) | J7: =IF(OR($I7="",LEFT($I7,1)="["),"",IFERROR(VLOOKUP(TRIM(IF(ISNUMBER(FIND(",",$I7)),LEFT($I7,FIND(",",$I7)-1),$I7)),'Mitre Techniques'!$A:$C,3,FALSE()),"Unknown technique")) | K7: =IF($J7="","",IFERROR(VLOOKUP(IF(ISNUMBER(FIND(",",$J7)),LEFT($J7,FIND(",",$J7)-1),$J7),'ATTACK and Kill Chain mapping'!$A:$B,2,FALSE()),"")) | L7: =IF($J7="","",IFERROR(VLOOKUP(IF(ISNUMBER(FIND(",",$J7)),LEFT($J7,FIND(",",$J7)-1),$J7),'ATTACK and Kill Chain mapping'!$A:$D,4,FALSE()),"")) | Q7: =IF(COUNT($N7:$P7)=0,"",$N7*$O7*$P7) | R7: =IF($Q7="","",1-$Q7)
A8: =IF($E8="","",COUNTIF($E:$E,$E8)) | B8: =IF($C8="","",VLOOKUP($C8,'L1 UC'!$C:$D,2,FALSE())) | C8: =IF($E8="","",LEFT($E8,FIND("-",$E8&"-")-1)) | D8: =IF($E8="","",VLOOKUP($E8,'L2 UC'!$C:$D,2,FALSE())) | E8: =IF($M8<>"",$M8,IF(COUNTIF('L2 UC'!$C:$C,$L8)>0,$L8,"")) | F8: =IF($E8="","",$E8&"-"&COUNTIF($E$2:$E8,$E8)) | J8: =IF(OR($I8="",LEFT($I8,1)="["),"",IFERROR(VLOOKUP(TRIM(IF(ISNUMBER(FIND(",",$I8)),LEFT($I8,FIND(",",$I8)-1),$I8)),'Mitre Techniques'!$A:$C,3,FALSE()),"Unknown technique")) | K8: =IF($J8="","",IFERROR(VLOOKUP(IF(ISNUMBER(FIND(",",$J8)),LEFT($J8,FIND(",",$J8)-1),$J8),'ATTACK and Kill Chain mapping'!$A:$B,2,FALSE()),"")) | L8: =IF($J8="","",IFERROR(VLOOKUP(IF(ISNUMBER(FIND(",",$J8)),LEFT($J8,FIND(",",$J8)-1),$J8),'ATTACK and Kill Chain mapping'!$A:$D,4,FALSE()),"")) | Q8: =IF(COUNT($N8:$P8)=0,"",$N8*$O8*$P8) | R8: =IF($Q8="","",1-$Q8)
A9: =IF($E9="","",COUNTIF($E:$E,$E9)) | B9: =IF($C9="","",VLOOKUP($C9,'L1 UC'!$C:$D,2,FALSE())) | C9: =IF($E9="","",LEFT($E9,FIND("-",$E9&"-")-1)) | D9: =IF($E9="","",VLOOKUP($E9,'L2 UC'!$C:$D,2,FALSE())) | E9: =IF($M9<>"",$M9,IF(COUNTIF('L2 UC'!$C:$C,$L9)>0,$L9,"")) | F9: =IF($E9="","",$E9&"-"&COUNTIF($E$2:$E9,$E9)) | J9: =IF(OR($I9="",LEFT($I9,1)="["),"",IFERROR(VLOOKUP(TRIM(IF(ISNUMBER(FIND(",",$I9)),LEFT($I9,FIND(",",$I9)-1),$I9)),'Mitre Techniques'!$A:$C,3,FALSE()),"Unknown technique")) | K9: =IF($J9="","",IFERROR(VLOOKUP(IF(ISNUMBER(FIND(",",$J9)),LEFT($J9,FIND(",",$J9)-1),$J9),'ATTACK and Kill Chain mapping'!$A:$B,2,FALSE()),"")) | L9: =IF($J9="","",IFERROR(VLOOKUP(IF(ISNUMBER(FIND(",",$J9)),LEFT($J9,FIND(",",$J9)-1),$J9),'ATTACK and Kill Chain mapping'!$A:$D,4,FALSE()),"")) | Q9: =IF(COUNT($N9:$P9)=0,"",$N9*$O9*$P9) | R9: =IF($Q9="","",1-$Q9)
A10: =IF($E10="","",COUNTIF($E:$E,$E10)) | B10: =IF($C10="","",VLOOKUP($C10,'L1 UC'!$C:$D,2,FALSE())) | C10: =IF($E10="","",LEFT($E10,FIND("-",$E10&"-")-1)) | D10: =IF($E10="","",VLOOKUP($E10,'L2 UC'!$C:$D,2,FALSE())) | E10: =IF($M10<>"",$M10,IF(COUNTIF('L2 UC'!$C:$C,$L10)>0,$L10,"")) | F10: =IF($E10="","",$E10&"-"&COUNTIF($E$2:$E10,$E10)) | J10: =IF(OR($I10="",LEFT($I10,1)="["),"",IFERROR(VLOOKUP(TRIM(IF(ISNUMBER(FIND(",",$I10)),LEFT($I10,FIND(",",$I10)-1),$I10)),'Mitre Techniques'!$A:$C,3,FALSE()),"Unknown technique")) | K10: =IF($J10="","",IFERROR(VLOOKUP(IF(ISNUMBER(FIND(",",$J10)),LEFT($J10,FIND(",",$J10)-1),$J10),'ATTACK and Kill Chain mapping'!$A:$B,2,FALSE()),"")) | L10: =IF($J10="","",IFERROR(VLOOKUP(IF(ISNUMBER(FIND(",",$J10)),LEFT($J10,FIND(",",$J10)-1),$J10),'ATTACK and Kill Chain mapping'!$A:$D,4,FALSE()),"")) | Q10: =IF(COUNT($N10:$P10)=0,"",$N10*$O10*$P10) | R10: =IF($Q10="","",1-$Q10)
A11: =IF($E11="","",COUNTIF($E:$E,$E11)) | B11: =IF($C11="","",VLOOKUP($C11,'L1 UC'!$C:$D,2,FALSE())) | C11: =IF($E11="","",LEFT($E11,FIND("-",$E11&"-")-1)) | D11: =IF($E11="","",VLOOKUP($E11,'L2 UC'!$C:$D,2,FALSE())) | E11: =IF($M11<>"",$M11,IF(COUNTIF('L2 UC'!$C:$C,$L11)>0,$L11,"")) | F11: =IF($E11="","",$E11&"-"&COUNTIF($E$2:$E11,$E11)) | J11: =IF(OR($I11="",LEFT($I11,1)="["),"",IFERROR(VLOOKUP(TRIM(IF(ISNUMBER(FIND(",",$I11)),LEFT($I11,FIND(",",$I11)-1),$I11)),'Mitre Techniques'!$A:$C,3,FALSE()),"Unknown technique")) | K11: =IF($J11="","",IFERROR(VLOOKUP(IF(ISNUMBER(FIND(",",$J11)),LEFT($J11,FIND(",",$J11)-1),$J11),'ATTACK and Kill Chain mapping'!$A:$B,2,FALSE()),"")) | L11: =IF($J11="","",IFERROR(VLOOKUP(IF(ISNUMBER(FIND(",",$J11)),LEFT($J11,FIND(",",$J11)-1),$J11),'ATTACK and Kill Chain mapping'!$A:$D,4,FALSE()),"")) | Q11: =IF(COUNT($N11:$P11)=0,"",$N11*$O11*$P11) | R11: =IF($Q11="","",1-$Q11)
A12: =IF($E12="","",COUNTIF($E:$E,$E12)) | B12: =IF($C12="","",VLOOKUP($C12,'L1 UC'!$C:$D,2,FALSE())) | C12: =IF($E12="","",LEFT($E12,FIND("-",$E12&"-")-1)) | D12: =IF($E12="","",VLOOKUP($E12,'L2 UC'!$C:$D,2,FALSE())) | E12: =IF($M12<>"",$M12,IF(COUNTIF('L2 UC'!$C:$C,$L12)>0,$L12,"")) | F12: =IF($E12="","",$E12&"-"&COUNTIF($E$2:$E12,$E12)) | J12: =IF(OR($I12="",LEFT($I12,1)="["),"",IFERROR(VLOOKUP(TRIM(IF(ISNUMBER(FIND(",",$I12)),LEFT($I12,FIND(",",$I12)-1),$I12)),'Mitre Techniques'!$A:$C,3,FALSE()),"Unknown technique")) | K12: =IF($J12="","",IFERROR(VLOOKUP(IF(ISNUMBER(FIND(",",$J12)),LEFT($J12,FIND(",",$J12)-1),$J12),'ATTACK and Kill Chain mapping'!$A:$B,2,FALSE()),"")) | L12: =IF($J12="","",IFERROR(VLOOKUP(IF(ISNUMBER(FIND(",",$J12)),LEFT($J12,FIND(",",$J12)-1),$J12),'ATTACK and Kill Chain mapping'!$A:$D,4,FALSE()),"")) | Q12: =IF(COUNT($N12:$P12)=0,"",$N12*$O12*$P12) | R12: =IF($Q12="","",1-$Q12)
A13: =IF($E13="","",COUNTIF($E:$E,$E13)) | B13: =IF($C13="","",VLOOKUP($C13,'L1 UC'!$C:$D,2,FALSE())) | C13: =IF($E13="","",LEFT($E13,FIND("-",$E13&"-")-1)) | D13: =IF($E13="","",VLOOKUP($E13,'L2 UC'!$C:$D,2,FALSE())) | E13: =IF($M13<>"",$M13,IF(COUNTIF('L2 UC'!$C:$C,$L13)>0,$L13,"")) | F13: =IF($E13="","",$E13&"-"&COUNTIF($E$2:$E13,$E13)) | J13: =IF(OR($I13="",LEFT($I13,1)="["),"",IFERROR(VLOOKUP(TRIM(IF(ISNUMBER(FIND(",",$I13)),LEFT($I13,FIND(",",$I13)-1),$I13)),'Mitre Techniques'!$A:$C,3,FALSE()),"Unknown technique")) | K13: =IF($J13="","",IFERROR(VLOOKUP(IF(ISNUMBER(FIND(",",$J13)),LEFT($J13,FIND(",",$J13)-1),$J13),'ATTACK and Kill Chain mapping'!$A:$B,2,FALSE()),"")) | L13: =IF($J13="","",IFERROR(VLOOKUP(IF(ISNUMBER(FIND(",",$J13)),LEFT($J13,FIND(",",$J13)-1),$J13),'ATTACK and Kill Chain mapping'!$A:$D,4,FALSE()),"")) | Q13: =IF(COUNT($N13:$P13)=0,"",$N13*$O13*$P13) | R13: =IF($Q13="","",1-$Q13)
A14: =IF($E14="","",COUNTIF($E:$E,$E14)) | B14: =IF($C14="","",VLOOKUP($C14,'L1 UC'!$C:$D,2,FALSE())) | C14: =IF($E14="","",LEFT($E14,FIND("-",$E14&"-")-1)) | D14: =IF($E14="","",VLOOKUP($E14,'L2 UC'!$C:$D,2,FALSE())) | E14: =IF($M14<>"",$M14,IF(COUNTIF('L2 UC'!$C:$C,$L14)>0,$L14,"")) | F14: =IF($E14="","",$E14&"-"&COUNTIF($E$2:$E14,$E14)) | J14: =IF(OR($I14="",LEFT($I14,1)="["),"",IFERROR(VLOOKUP(TRIM(IF(ISNUMBER(FIND(",",$I14)),LEFT($I14,FIND(",",$I14)-1),$I14)),'Mitre Techniques'!$A:$C,3,FALSE()),"Unknown technique")) | K14: =IF($J14="","",IFERROR(VLOOKUP(IF(ISNUMBER(FIND(",",$J14)),LEFT($J14,FIND(",",$J14)-1),$J14),'ATTACK and Kill Chain mapping'!$A:$B,2,FALSE()),"")) | L14: =IF($J14="","",IFERROR(VLOOKUP(IF(ISNUMBER(FIND(",",$J14)),LEFT($J14,FIND(",",$J14)-1),$J14),'ATTACK and Kill Chain mapping'!$A:$D,4,FALSE()),"")) | Q14: =IF(COUNT($N14:$P14)=0,"",$N14*$O14*$P14) | R14: =IF($Q14="","",1-$Q14)
... A500: =IF($E500="","",COUNTIF($E:$E,$E500)) | B500: =IF($C500="","",VLOOKUP($C500,'L1 UC'!$C:$D,2,FALSE())) | C500: =IF($E500="","",LEFT($E500,FIND("-",$E500&"-")-1)) | D500: =IF($E500="","",VLOOKUP($E500,'L2 UC'!$C:$D,2,FALSE())) | E500: =IF($M500<>"",$M500,IF(COUNTIF('L2 UC'!$C:$C,$L500)>0,$L500,"")) | F500: =IF($E500="","",$E500&"-"&COUNTIF($E$2:$E500,$E500)) | J500: =IF(OR($I500="",LEFT($I500,1)="["),"",IFERROR(VLOOKUP(TRIM(IF(ISNUMBER(FIND(",",$I500)),LEFT($I500,FIND(",",$I500)-1),$I500)),'Mitre Techniques'!$A:$C,3,FALSE()),"Unknown technique")) | K500: =IF($J500="","",IFERROR(VLOOKUP(IF(ISNUMBER(FIND(",",$J500)),LEFT($J500,FIND(",",$J500)-1),$J500),'ATTACK and Kill Chain mapping'!$A:$B,2,FALSE()),"")) | L500: =IF($J500="","",IFERROR(VLOOKUP(IF(ISNUMBER(FIND(",",$J500)),LEFT($J500,FIND(",",$J500)-1),$J500),'ATTACK and Kill Chain mapping'!$A:$D,4,FALSE()),"")) | Q500: =IF(COUNT($N500:$P500)=0,"",$N500*$O500*$P500) | R500: =IF($Q500="","",1-$Q500)

Sheet Drivers
B2: Business Drivers
B4: List high-level business drivers that are input into SOC use cases
B6: High Level Business Requirements
B7: ID | C7: Business Drivers | D7: Description
B8: BD-01 | C8: Direct Financial Loss | D8: Prevent Loss due to Financial theft Prevent Loss due to Theft of IP Prevent Loss due to Fraud Prevent Loss due to Sabotage
B9: BD-02 | C9: Reputational Damage | D9: Prevent Reputational damage due to loss of information (customer information, etc.) Prevent Reputational damage due to (Perceived) lack of information security
B10: BD-03 | C10: Legal and Regulatory Obligations | D10: Avoid missed business opportunities due to regulator limitations Prevent penalties due to missed regulator requirements
B11: BD-04 | C11: Enable Business | D11: Assist and enable business to use new channels and methods in order to be competative Reduce risk by implementing Security Monitoring and Response
B12: BD-05 | C12: Business Continuity | D12: Early detection of threats to provide business continuity Prevent business against data loss (deletion) Prevent outages of critical business services
B13: BD-06 | C13: Strategic and Commercial interests | D13: Damage to strategic and commercial interests, e.g. misleading management information, inefficient operation, disadavantage in negotiations etc.
B15: Compliance Drivers
B17: List compliance drivers from internal policies and external regulators. Use the ID of the policy rule itself as a reference
B19: Compliance Requirements
B20: ID | C20: Compliance Driver | D20: Description
B21: REF | C21: Internal Security Policy
B22: REF | C22: Internal Security Policy
B23: REF | C23: Internal Security Policy
B24: REF | C24: Internal Security Policy
B25: REF | C25: Internal Security Policy
B26: REF | C26: External Regulator #1
B27: REF | C27: External Regulator #1
B28: REF | C28: External Regulator #1
B29: REF | C29: External Regulator #1
B30: REF | C30: External Regulator #1
B31: REF | C31: External Regulator #2
B32: REF | C32: External Regulator #2
... B35: REF | C35: External Regulator #2

Sheet References
B2: Threat Actors (CSAN 2017)
B3: Actor | C3: Description
B4: Professional Criminals | C4: Actors that perform malicious activity to make money. These criminals have revenue models, ranging from selling malware to DDoS extortion threat and stealing money using banking malware.
B5: State Actors | C5: Actors that perform malicious activity on behalf of their country. Such activities are usually espionage, but may also include disruption of critical infrastructure of another country. These actors have a lot of capabilities and the resources and perseverance to carry out long and covert operations.
B6: Terrorists | C6: Actors that perform malicious activity to support terrorist organizations in their cause. Their activities will usually focus on disruption through DDoS attacks and defacement. Generally speaking, these actors do not have a lot of capabilities.
B7: Hacktivists, Cyber vandals and Script Kiddies | C7: Hacktivist actors have similar activities as terrorist actors, but a different motive. Capabilities depend on the hacktivist group and composition. Cyber vandals and script kiddies usually carry out the activities for personal recognition. Their capabilities vary, but resources are limited.
B8: Internal Actors | C8: Actors that perform their activities from within the organization. This may include unintentional behavior, but can also originate from a grudge against the employer.
B9: Private Organizations | C9: Actors from other organizations. The CSAN differentiates 3 motives: attacking confidentiality for financial gain, improve their competitive position or to use (personal) data collected without consent.
B10: Multiple Actors | C10: Multiple primary actors may carry out this malicious activity
B12: Detection Technologies
B13: Technology | C13: Description
B14: SIEM | C14: Security Information and Event Management system. Such systems are usually key to SOC detection capabilities
B15: Big data analytics | C15: A big data platform to gather information from the network that can be used for anomaly detection and hunting capabilities
B16: NIDS/NIPS | C16: Network Intrusion Detection (or Prevention) System. Network-based protection or detection mechanism that identifies attacks on the network.
B17: HIPS | C17: Host Intrusion Detection (or Prevention) System. Host-based protection or detection mechanism that identifies attacks against the host.
B18: Anti-malware | C18: Host-based protection mechanism that protects against malware threats.
B19: Network anomaly detection | C19: Detection technology that uses network information (for example: flows) to detect aberrant behavior
B20: Email protection | C20: Systems protecting from email-based threats, mostly malicious attachments
B21: … | C21: …
B23: Log Sources
B24: Log source | C24: Description
B25: Firewall | C25: Logging from firewall devices. Usually, these are network firewalls. Host-based firewalls may also provide logging. Such logging contains connections made by possible attackers and can be used to identify network-based attacks, such as session attacks and scanning
B26: Network traffic | C26: Actual network traffic. This can be netflow data, or actual traffic. Can be analyzed for network based anomalies
